Traceback (most recent call last):
  File "<pyshell#12>", line 2, in <module>
Exception: This is the error message.
